I'm sorry, but an uncaught exception occurred.

While running game code:
  File "game/chapter3.rpy", line 271, in script
    kevin "Which aspect does this belong to?"
Exception: Sayer 'kevin' is not defined.

-- Full Traceback ------------------------------------------------------------

Full traceback:
  File "game/chapter3.rpy", line 271, in script
    kevin "Which aspect does this belong to?"
  File "renpy/ast.py", line 681, in execute
    who = eval_who(self.who, self.who_fast)
  File "renpy/ast.py", line 574, in eval_who
    raise Exception("Sayer '%s' is not defined." % who)
Exception: Sayer 'kevin' is not defined.

Windows-10-10.0.22000
Ren'Py 7.4.10.2178
Healthy and Safety 1.0
Sun Jul 10 10:10:51 2022
